<?xml version="1.0" ?>
<!-- =================================================================================== -->
<!-- |    This document was autogenerated by xacro from /home/drojas/dlo_ws/src/wire_manipulation/wire_manipulation_description/urdf/base_scene.xacro | -->
<!-- |    EDITING THIS FILE BY HAND IS NOT RECOMMENDED                                 | -->
<!-- =================================================================================== -->
<robot name="base_scene">
    <!-- World link -->
    <link name="world" />
    <link name="panel_1">
        <visual>
            <origin rpy="0 0 0" xyz="0 0 0" />
            <geometry>
                <box size="0.02 0.762 0.6096" />
            </geometry>
            <material name="Cyan">
                <color rgba="0 1.0 1.0 1.0" />
            </material>
        </visual>
        <collision>
            <origin rpy="0 0 0" xyz="0 0 0" />
            <geometry>
                <box size="0.02 0.762 0.6096" />
            </geometry>
        </collision>
        <inertial>
            <mass value="0.1" />
            <origin xyz="0 0 0" rpy="0 0 0" />
            <inertia ixx="0.03" iyy="0.03" izz="0.03" ixy="0.0" ixz="0.0" iyz="0.0" />
        </inertial>
    </link>
    <link name="panel_2">
        <visual>
            <origin rpy="0 0 0" xyz="0 0 0" />
            <geometry>
                <box size="0.4572 0.02 0.6096" />
            </geometry>
            <material name="Cyan">
                <color rgba="0 1.0 1.0 1.0" />
            </material>
        </visual>
        <collision>
            <origin rpy="0 0 0" xyz="0 0 0" />
            <geometry>
                <box size="0.4572 0.02 0.6096" />
            </geometry>
        </collision>
        <inertial>
            <mass value="0.1" />
            <origin xyz="0 0 0" rpy="0 0 0" />
            <inertia ixx="0.03" iyy="0.03" izz="0.03" ixy="0.0" ixz="0.0" iyz="0.0" />
        </inertial>
    </link>
    <link name="ground">
        <collision>
            <origin rpy="0 0 0" xyz="0 0 0" />
            <geometry>
                <box size="5 5 0.02" />
            </geometry>
        </collision>
        <inertial>
            <mass value="0.1" />
            <origin xyz="0 0 0" rpy="0 0 0" />
            <inertia ixx="0.03" iyy="0.03" izz="0.03" ixy="0.0" ixz="0.0" iyz="0.0" />
        </inertial>
    </link>
    <joint name="panel_joint" type="fixed">
        <parent link="panel_1" />
        <child link="panel_2" />
        <origin xyz="-0.2286 -0.391 0" />
    </joint>
    <joint name="panel_to_world" type="fixed">
        <parent link="world" />
        <child link="panel_1" />
        <origin xyz="0.5334 -0.0381 0.3048" />
    </joint>
    <joint name="ground_to_world" type="fixed">
        <parent link="world" />
        <child link="ground" />
        <origin xyz="0 0 -0.01" />
    </joint>
    <material name="interbotix_black">
        <texture filename="package://interbotix_xsarm_descriptions/meshes/interbotix_black.png" />
    </material>
    <transmission name="a_bot_waist_trans">
        <type>transmission_interface/SimpleTransmission</type>
        <joint name="a_bot_waist">
            <hardwareInterface>hardware_interface/EffortJointInterface</hardwareInterface>
        </joint>
        <actuator name="a_bot_waist_motor">
            <mechanicalReduction>1</mechanicalReduction>
            <hardwareInterface>hardware_interface/EffortJointInterface</hardwareInterface>
        </actuator>
    </transmission>
    <transmission name="a_bot_shoulder_trans">
        <type>transmission_interface/SimpleTransmission</type>
        <joint name="a_bot_shoulder">
            <hardwareInterface>hardware_interface/EffortJointInterface</hardwareInterface>
        </joint>
        <actuator name="a_bot_shoulder_motor">
            <mechanicalReduction>1</mechanicalReduction>
            <hardwareInterface>hardware_interface/EffortJointInterface</hardwareInterface>
        </actuator>
    </transmission>
    <transmission name="a_bot_elbow_trans">
        <type>transmission_interface/SimpleTransmission</type>
        <joint name="a_bot_elbow">
            <hardwareInterface>hardware_interface/EffortJointInterface</hardwareInterface>
        </joint>
        <actuator name="a_bot_elbow_motor">
            <mechanicalReduction>1</mechanicalReduction>
            <hardwareInterface>hardware_interface/EffortJointInterface</hardwareInterface>
        </actuator>
    </transmission>
    <transmission name="a_bot_forearm_roll_trans">
        <type>transmission_interface/SimpleTransmission</type>
        <joint name="a_bot_forearm_roll">
            <hardwareInterface>hardware_interface/EffortJointInterface</hardwareInterface>
        </joint>
        <actuator name="a_bot_forearm_roll_motor">
            <mechanicalReduction>1</mechanicalReduction>
            <hardwareInterface>hardware_interface/EffortJointInterface</hardwareInterface>
        </actuator>
    </transmission>
    <transmission name="a_bot_wrist_angle_trans">
        <type>transmission_interface/SimpleTransmission</type>
        <joint name="a_bot_wrist_angle">
            <hardwareInterface>hardware_interface/EffortJointInterface</hardwareInterface>
        </joint>
        <actuator name="a_bot_wrist_angle_motor">
            <mechanicalReduction>1</mechanicalReduction>
            <hardwareInterface>hardware_interface/EffortJointInterface</hardwareInterface>
        </actuator>
    </transmission>
    <transmission name="a_bot_wrist_rotate_trans">
        <type>transmission_interface/SimpleTransmission</type>
        <joint name="a_bot_wrist_rotate">
            <hardwareInterface>hardware_interface/EffortJointInterface</hardwareInterface>
        </joint>
        <actuator name="a_bot_wrist_rotate_motor">
            <mechanicalReduction>1</mechanicalReduction>
            <hardwareInterface>hardware_interface/EffortJointInterface</hardwareInterface>
        </actuator>
    </transmission>
    <transmission name="a_bot_left_finger_trans">
        <type>transmission_interface/SimpleTransmission</type>
        <joint name="a_bot_left_finger">
            <hardwareInterface>hardware_interface/EffortJointInterface</hardwareInterface>
        </joint>
        <actuator name="a_bot_left_finger_motor">
            <mechanicalReduction>1</mechanicalReduction>
            <hardwareInterface>hardware_interface/EffortJointInterface</hardwareInterface>
        </actuator>
    </transmission>
    <transmission name="a_bot_right_finger_trans">
        <type>transmission_interface/SimpleTransmission</type>
        <joint name="a_bot_right_finger">
            <hardwareInterface>hardware_interface/EffortJointInterface</hardwareInterface>
        </joint>
        <actuator name="a_bot_right_finger_motor">
            <mechanicalReduction>1</mechanicalReduction>
            <hardwareInterface>hardware_interface/EffortJointInterface</hardwareInterface>
        </actuator>
    </transmission>
    <gazebo reference="a_bot_base_link">
        <kp>1000000.0</kp>
        <kd>1.0</kd>
        <mu1>0.8</mu1>
        <mu2>0.8</mu2>
        <maxVel>0.0</maxVel>
        <minDepth>0.001</minDepth>
        <selfCollide>true</selfCollide>
        <plugin name="gazebo_ros_control">
            <robotNamespace>/</robotNamespace>
        </plugin>
    </gazebo>
    <gazebo reference="a_bot_shoulder_link">
        <kp>1000000.0</kp>
        <kd>1.0</kd>
        <mu1>0.8</mu1>
        <mu2>0.8</mu2>
        <maxVel>0.0</maxVel>
        <minDepth>0.001</minDepth>
        <selfCollide>true</selfCollide>
    </gazebo>
    <gazebo reference="a_bot_upper_arm_link">
        <kp>1000000.0</kp>
        <kd>1.0</kd>
        <mu1>0.8</mu1>
        <mu2>0.8</mu2>
        <maxVel>0.0</maxVel>
        <minDepth>0.001</minDepth>
        <selfCollide>true</selfCollide>
    </gazebo>
    <gazebo reference="a_bot_upper_forearm_link">
        <kp>1000000.0</kp>
        <kd>1.0</kd>
        <mu1>0.8</mu1>
        <mu2>0.8</mu2>
        <maxVel>0.0</maxVel>
        <minDepth>0.001</minDepth>
        <selfCollide>true</selfCollide>
    </gazebo>
    <gazebo reference="a_bot_lower_forearm_link">
        <kp>1000000.0</kp>
        <kd>1.0</kd>
        <mu1>0.8</mu1>
        <mu2>0.8</mu2>
        <maxVel>0.0</maxVel>
        <minDepth>0.001</minDepth>
        <selfCollide>true</selfCollide>
    </gazebo>
    <gazebo reference="a_bot_wrist_link">
        <kp>1000000.0</kp>
        <kd>1.0</kd>
        <mu1>0.8</mu1>
        <mu2>0.8</mu2>
        <maxVel>0.0</maxVel>
        <minDepth>0.001</minDepth>
        <selfCollide>true</selfCollide>
    </gazebo>
    <gazebo reference="a_bot_gripper_link">
        <kp>1000000.0</kp>
        <kd>1.0</kd>
        <mu1>0.8</mu1>
        <mu2>0.8</mu2>
        <maxVel>0.0</maxVel>
        <minDepth>0.001</minDepth>
        <selfCollide>true</selfCollide>
    </gazebo>
    <gazebo reference="a_bot_gripper_prop_link">
        <kp>1000000.0</kp>
        <kd>1.0</kd>
        <mu1>0.8</mu1>
        <mu2>0.8</mu2>
        <maxVel>0.0</maxVel>
        <minDepth>0.001</minDepth>
        <selfCollide>true</selfCollide>
    </gazebo>
    <gazebo reference="a_bot_gripper_bar_link">
        <kp>1000000.0</kp>
        <kd>1.0</kd>
        <mu1>0.8</mu1>
        <mu2>0.8</mu2>
        <maxVel>0.0</maxVel>
        <minDepth>0.001</minDepth>
        <selfCollide>true</selfCollide>
    </gazebo>
    <gazebo reference="a_bot_left_finger_link">
        <kp>1000000.0</kp>
        <kd>1.0</kd>
        <mu1>0.8</mu1>
        <mu2>0.8</mu2>
        <maxVel>0.0</maxVel>
        <minDepth>0.001</minDepth>
        <selfCollide>true</selfCollide>
    </gazebo>
    <gazebo reference="a_bot_right_finger_link">
        <kp>1000000.0</kp>
        <kd>1.0</kd>
        <mu1>0.8</mu1>
        <mu2>0.8</mu2>
        <maxVel>0.0</maxVel>
        <minDepth>0.001</minDepth>
        <selfCollide>true</selfCollide>
    </gazebo>
    <gazebo reference="a_bot_waist">
        <implicitSpringDamper>true</implicitSpringDamper>
        <disableFixedJointLumping>true</disableFixedJointLumping>
    </gazebo>
    <gazebo reference="a_bot_shoulder">
        <implicitSpringDamper>true</implicitSpringDamper>
        <disableFixedJointLumping>true</disableFixedJointLumping>
    </gazebo>
    <gazebo reference="a_bot_elbow">
        <implicitSpringDamper>true</implicitSpringDamper>
        <disableFixedJointLumping>true</disableFixedJointLumping>
    </gazebo>
    <gazebo reference="a_bot_forearm_roll">
        <implicitSpringDamper>true</implicitSpringDamper>
        <disableFixedJointLumping>true</disableFixedJointLumping>
    </gazebo>
    <gazebo reference="a_bot_wrist_angle">
        <implicitSpringDamper>true</implicitSpringDamper>
        <disableFixedJointLumping>true</disableFixedJointLumping>
    </gazebo>
    <gazebo reference="a_bot_wrist_rotate">
        <implicitSpringDamper>true</implicitSpringDamper>
        <disableFixedJointLumping>true</disableFixedJointLumping>
    </gazebo>
    <gazebo reference="a_bot_ee_arm">
        <implicitSpringDamper>true</implicitSpringDamper>
        <disableFixedJointLumping>true</disableFixedJointLumping>
    </gazebo>
    <gazebo reference="a_bot_gripper">
        <implicitSpringDamper>true</implicitSpringDamper>
        <disableFixedJointLumping>true</disableFixedJointLumping>
    </gazebo>
    <gazebo reference="a_bot_gripper_bar">
        <implicitSpringDamper>true</implicitSpringDamper>
        <disableFixedJointLumping>true</disableFixedJointLumping>
    </gazebo>
    <gazebo reference="a_bot_ee_bar">
        <implicitSpringDamper>true</implicitSpringDamper>
        <disableFixedJointLumping>true</disableFixedJointLumping>
    </gazebo>
    <gazebo reference="a_bot_left_finger">
        <implicitSpringDamper>true</implicitSpringDamper>
        <disableFixedJointLumping>true</disableFixedJointLumping>
    </gazebo>
    <gazebo reference="a_bot_right_finger">
        <implicitSpringDamper>true</implicitSpringDamper>
        <disableFixedJointLumping>true</disableFixedJointLumping>
    </gazebo>
    <gazebo reference="a_bot_ee_gripper">
        <implicitSpringDamper>true</implicitSpringDamper>
        <disableFixedJointLumping>true</disableFixedJointLumping>
    </gazebo>
    <link name="a_bot_base_link">
        <visual>
            <origin rpy="0 0 1.5707963267948966" xyz="0 0 0" />
            <geometry>
                <mesh filename="package://interbotix_xsarm_descriptions/meshes/vx300s_meshes/vx300s_1_base.stl" scale="0.001 0.001 0.001" />
            </geometry>
            <material name="interbotix_black" />
        </visual>
        <collision>
            <origin rpy="0 0 1.5707963267948966" xyz="0 0 0" />
            <geometry>
                <mesh filename="package://interbotix_xsarm_descriptions/meshes/vx300s_meshes/vx300s_1_base.stl" scale="0.001 0.001 0.001" />
            </geometry>
        </collision>
        <inertial>
            <origin rpy="0 0 1.5707963267948966" xyz="-0.0534774000 -0.0005625750 0.0205961000" />
            <mass value="0.969034" />
            <inertia ixx="0.0060240000" ixy="0.0000471300" ixz="0.0000038510" iyy="0.0017000000" iyz="-0.0000841500" izz="0.0071620000" />
        </inertial>
    </link>
    <joint name="a_bot_waist" type="revolute">
        <axis xyz="0 0 1" />
        <limit effort="10" lower="-3.141582653589793" upper="3.141582653589793" velocity="3.141592653589793" />
        <origin rpy="0 0 0" xyz="0 0 0.079" />
        <parent link="a_bot_base_link" />
        <child link="a_bot_shoulder_link" />
        <dynamics friction="0.1" />
    </joint>
    <link name="a_bot_shoulder_link">
        <visual>
            <origin rpy="0 0 1.5707963267948966" xyz="0 0 -0.003" />
            <geometry>
                <mesh filename="package://interbotix_xsarm_descriptions/meshes/vx300s_meshes/vx300s_2_shoulder.stl" scale="0.001 0.001 0.001" />
            </geometry>
            <material name="interbotix_black" />
        </visual>
        <collision>
            <origin rpy="0 0 1.5707963267948966" xyz="0 0 -0.003" />
            <geometry>
                <mesh filename="package://interbotix_xsarm_descriptions/meshes/vx300s_meshes/vx300s_2_shoulder.stl" scale="0.001 0.001 0.001" />
            </geometry>
        </collision>
        <inertial>
            <origin rpy="0 0 1.5707963267948966" xyz="0.0002592330 -0.0000033552 0.0116129000" />
            <mass value="0.798614" />
            <inertia ixx="0.0009388000" ixy="-0.0000000010" ixz="-0.0000000191" iyy="0.0011380000" iyz="0.0000059568" izz="0.0012010000" />
        </inertial>
    </link>
    <joint name="a_bot_shoulder" type="revolute">
        <axis xyz="0 1 0" />
        <limit effort="20" lower="-1.8500490071139892" upper="1.2566370614359172" velocity="3.141592653589793" />
        <origin rpy="0 0 0" xyz="0 0 0.04805" />
        <parent link="a_bot_shoulder_link" />
        <child link="a_bot_upper_arm_link" />
        <dynamics friction="0.1" />
    </joint>
    <link name="a_bot_upper_arm_link">
        <visual>
            <origin rpy="0 0 1.5707963267948966" xyz="0 0 0" />
            <geometry>
                <mesh filename="package://interbotix_xsarm_descriptions/meshes/vx300s_meshes/vx300s_3_upper_arm.stl" scale="0.001 0.001 0.001" />
            </geometry>
            <material name="interbotix_black" />
        </visual>
        <collision>
            <origin rpy="0 0 1.5707963267948966" xyz="0 0 0" />
            <geometry>
                <mesh filename="package://interbotix_xsarm_descriptions/meshes/vx300s_meshes/vx300s_3_upper_arm.stl" scale="0.001 0.001 0.001" />
            </geometry>
        </collision>
        <inertial>
            <origin rpy="0 0 1.5707963267948966" xyz="0.0206949000 0.0000000004 0.2264590000" />
            <mass value="0.792592" />
            <inertia ixx="0.0089250000" ixy="0.0000000000" ixz="0.0000000000" iyy="0.0089370000" iyz="0.0012010000" izz="0.0009357000" />
        </inertial>
    </link>
    <joint name="a_bot_elbow" type="revolute">
        <axis xyz="0 1 0" />
        <limit effort="15" lower="-1.7627825445142729" upper="1.6057029118347832" velocity="3.141592653589793" />
        <origin rpy="0 0 0" xyz="0.05955 0 0.3" />
        <parent link="a_bot_upper_arm_link" />
        <child link="a_bot_upper_forearm_link" />
        <dynamics friction="0.1" />
    </joint>
    <link name="a_bot_upper_forearm_link">
        <visual>
            <origin rpy="0 0 0" xyz="0 0 0" />
            <geometry>
                <mesh filename="package://interbotix_xsarm_descriptions/meshes/vx300s_meshes/vx300s_4_upper_forearm.stl" scale="0.001 0.001 0.001" />
            </geometry>
            <material name="interbotix_black" />
        </visual>
        <collision>
            <origin rpy="0 0 0" xyz="0 0 0" />
            <geometry>
                <mesh filename="package://interbotix_xsarm_descriptions/meshes/vx300s_meshes/vx300s_4_upper_forearm.stl" scale="0.001 0.001 0.001" />
            </geometry>
        </collision>
        <inertial>
            <origin rpy="0 0 0" xyz="0.105723 0 0" />
            <mass value="0.322228" />
            <inertia ixx="0.0001524000" ixy="-0.0000188300" ixz="-0.0000084064" iyy="0.0013420000" iyz="0.0000012564" izz="0.0014410000" />
        </inertial>
    </link>
    <joint name="a_bot_forearm_roll" type="revolute">
        <axis xyz="1 0 0" />
        <limit effort="2" lower="-3.141582653589793" upper="3.141582653589793" velocity="3.141592653589793" />
        <origin rpy="0 0 0" xyz="0.2 0 0" />
        <parent link="a_bot_upper_forearm_link" />
        <child link="a_bot_lower_forearm_link" />
        <dynamics friction="0.1" />
    </joint>
    <link name="a_bot_lower_forearm_link">
        <visual>
            <origin rpy="3.141592653589793 0 0" xyz="0 0 0" />
            <geometry>
                <mesh filename="package://interbotix_xsarm_descriptions/meshes/vx300s_meshes/vx300s_5_lower_forearm.stl" scale="0.001 0.001 0.001" />
            </geometry>
            <material name="interbotix_black" />
        </visual>
        <collision>
            <origin rpy="3.141592653589793 0 0" xyz="0 0 0" />
            <geometry>
                <mesh filename="package://interbotix_xsarm_descriptions/meshes/vx300s_meshes/vx300s_5_lower_forearm.stl" scale="0.001 0.001 0.001" />
            </geometry>
        </collision>
        <inertial>
            <origin rpy="3.141592653589793 0 0" xyz="0.0513477000 0.0068046200 0" />
            <mass value="0.414823" />
            <inertia ixx="0.0001753000" ixy="-0.0000852800" ixz="0" iyy="0.0005269000" iyz="0" izz="0.0005911000" />
        </inertial>
    </link>
    <joint name="a_bot_wrist_angle" type="revolute">
        <axis xyz="0 1 0" />
        <limit effort="5" lower="-1.8675022996339325" upper="2.234021442552742" velocity="3.141592653589793" />
        <origin rpy="0 0 0" xyz="0.1 0 0" />
        <parent link="a_bot_lower_forearm_link" />
        <child link="a_bot_wrist_link" />
        <dynamics friction="0.1" />
    </joint>
    <link name="a_bot_wrist_link">
        <visual>
            <origin rpy="0 0 1.5707963267948966" xyz="0 0 0" />
            <geometry>
                <mesh filename="package://interbotix_xsarm_descriptions/meshes/vx300s_meshes/vx300s_6_wrist.stl" scale="0.001 0.001 0.001" />
            </geometry>
            <material name="interbotix_black" />
        </visual>
        <collision>
            <origin rpy="0 0 1.5707963267948966" xyz="0 0 0" />
            <geometry>
                <mesh filename="package://interbotix_xsarm_descriptions/meshes/vx300s_meshes/vx300s_6_wrist.stl" scale="0.001 0.001 0.001" />
            </geometry>
        </collision>
        <inertial>
            <origin rpy="0 0 1.5707963267948966" xyz="0.0467430000 -0.0000076652 0.0105650000" />
            <mass value="0.115395" />
            <inertia ixx="0.0000463100" ixy="0.0000000195" ixz="0.0000000023" iyy="0.0000451400" iyz="0.0000042002" izz="0.0000527000" />
        </inertial>
    </link>
    <joint name="a_bot_wrist_rotate" type="revolute">
        <axis xyz="1 0 0" />
        <limit effort="1" lower="-3.141582653589793" upper="3.141582653589793" velocity="3.141592653589793" />
        <origin rpy="0 0 0" xyz="0.069744 0 0" />
        <parent link="a_bot_wrist_link" />
        <child link="a_bot_gripper_link" />
        <dynamics friction="0.1" />
    </joint>
    <link name="a_bot_gripper_link">
        <visual>
            <origin rpy="0 0 1.5707963267948966" xyz="-0.02 0 0" />
            <geometry>
                <mesh filename="package://interbotix_xsarm_descriptions/meshes/vx300s_meshes/vx300s_7_gripper.stl" scale="0.001 0.001 0.001" />
            </geometry>
            <material name="interbotix_black" />
        </visual>
        <collision>
            <origin rpy="0 0 1.5707963267948966" xyz="-0.02 0 0" />
            <geometry>
                <mesh filename="package://interbotix_xsarm_descriptions/meshes/vx300s_meshes/vx300s_7_gripper.stl" scale="0.001 0.001 0.001" />
            </geometry>
        </collision>
        <inertial>
            <origin rpy="0 0 1.5707963267948966" xyz="0.0230010000 0.0000000000 0.0115230000" />
            <mass value="0.097666" />
            <inertia ixx="0.0000326800" ixy="0.0000000000" ixz="0.0000000000" iyy="0.0000243600" iyz="0.0000002785" izz="0.0000211900" />
        </inertial>
    </link>
    <joint name="a_bot_ee_arm" type="fixed">
        <axis xyz="1 0 0" />
        <origin rpy="0 0 0" xyz="0.042825 0 0" />
        <parent link="a_bot_gripper_link" />
        <child link="a_bot_ee_arm_link" />
    </joint>
    <!-- no visual -->
    <link name="a_bot_ee_arm_link">
        <inertial>
            <mass value="0.001" />
            <inertia ixx="0.0001" ixy="0" ixz="0" iyy="0.0001" iyz="0" izz="0.0001" />
        </inertial>
    </link>
    <joint name="a_bot_gripper_bar" type="fixed">
        <axis xyz="1 0 0" />
        <origin rpy="0 0 0" xyz="0 0 0" />
        <parent link="a_bot_ee_arm_link" />
        <child link="a_bot_gripper_bar_link" />
    </joint>
    <link name="a_bot_gripper_bar_link">
        <visual>
            <origin rpy="0 0 1.5707963267948966" xyz="-0.063 0 0" />
            <geometry>
                <mesh filename="package://interbotix_xsarm_descriptions/meshes/vx300s_meshes/vx300s_9_gripper_bar.stl" scale="0.001 0.001 0.001" />
            </geometry>
            <material name="interbotix_black" />
        </visual>
        <collision>
            <origin rpy="0 0 1.5707963267948966" xyz="-0.063 0 0" />
            <geometry>
                <mesh filename="package://interbotix_xsarm_descriptions/meshes/vx300s_meshes/vx300s_9_gripper_bar.stl" scale="0.001 0.001 0.001" />
            </geometry>
        </collision>
        <inertial>
            <origin rpy="0 0 1.5707963267948966" xyz="0.0067940000 -0.0000004272 -0.0007760000" />
            <mass value="0.150986" />
            <inertia ixx="0.0000789500" ixy="-0.0000000012" ixz="0.0000001341" iyy="0.0003283000" iyz="0.0000017465" izz="0.0003095000" />
        </inertial>
    </link>
    <joint name="a_bot_ee_bar" type="fixed">
        <axis xyz="1 0 0" />
        <origin rpy="0 0 0" xyz="0.025875 0 0" />
        <parent link="a_bot_gripper_bar_link" />
        <child link="a_bot_fingers_link" />
    </joint>
    <!-- no visual -->
    <link name="a_bot_fingers_link">
        <inertial>
            <mass value="0.001" />
            <inertia ixx="0.0001" ixy="0" ixz="0" iyy="0.0001" iyz="0" izz="0.0001" />
        </inertial>
    </link>
    <joint name="a_bot_left_finger" type="prismatic">
        <axis xyz="0 1 0" />
        <limit effort="5" lower="0.021" upper="0.057" velocity="1" />
        <origin rpy="0 0 0" xyz="0 0 0" />
        <parent link="a_bot_fingers_link" />
        <child link="a_bot_left_finger_link" />
        <dynamics friction="0.1" />
    </joint>
    <link name="a_bot_left_finger_link">
        <visual>
            <origin rpy="1.5707963267948966 -3.141592653589793 1.5707963267948966" xyz="-0.0404 -0.0575 0" />
            <geometry>
                <mesh filename="package://interbotix_xsarm_descriptions/meshes/vx300s_meshes/vx300s_10_gripper_finger.stl" scale="0.001 0.001 0.001" />
            </geometry>
            <material name="interbotix_black" />
        </visual>
        <collision>
            <origin rpy="1.5707963267948966 -3.141592653589793 1.5707963267948966" xyz="-0.0404 -0.0575 0" />
            <geometry>
                <mesh filename="package://interbotix_xsarm_descriptions/meshes/vx300s_meshes/vx300s_10_gripper_finger.stl" scale="0.001 0.001 0.001" />
            </geometry>
        </collision>
        <inertial>
            <origin rpy="3.141592653589793 3.141592653589793 1.5707963267948966" xyz="0.0173440000 -0.0060692000 0.0000000000" />
            <mass value="0.034796" />
            <inertia ixx="0.0000243300" ixy="-0.0000024004" ixz="0.0000000000" iyy="0.0000125500" iyz="0.0000000000" izz="0.0000141700" />
        </inertial>
    </link>
    <joint name="a_bot_right_finger" type="prismatic">
        <axis xyz="0 1 0" />
        <limit effort="5" lower="-0.057" upper="-0.021" velocity="1" />
        <origin rpy="0 0 0" xyz="0 0 0" />
        <parent link="a_bot_fingers_link" />
        <child link="a_bot_right_finger_link" />
        <dynamics friction="0.1" />
        <mimic joint="a_bot_left_finger" multiplier="-1" offset="0" />
    </joint>
    <link name="a_bot_right_finger_link">
        <visual>
            <origin rpy="-1.5707963267948966 3.141592653589793 -1.5707963267948966" xyz="-0.0404 0.0575 0 " />
            <geometry>
                <mesh filename="package://interbotix_xsarm_descriptions/meshes/vx300s_meshes/vx300s_10_gripper_finger.stl" scale="0.001 0.001 0.001" />
            </geometry>
            <material name="interbotix_black" />
        </visual>
        <collision>
            <origin rpy="-1.5707963267948966 3.141592653589793 -1.5707963267948966" xyz="-0.0404 0.0575 0 " />
            <geometry>
                <mesh filename="package://interbotix_xsarm_descriptions/meshes/vx300s_meshes/vx300s_10_gripper_finger.stl" scale="0.001 0.001 0.001" />
            </geometry>
        </collision>
        <inertial>
            <origin rpy="0 3.141592653589793 1.5707963267948966" xyz="0.0173440000 0.0060692000  0.0000000000" />
            <mass value="0.034796" />
            <inertia ixx="0.0000243300" ixy="0.0000024001" ixz="0.0000000000" iyy="0.0000125500" iyz="0.0000000000" izz="0.0000141700" />
        </inertial>
    </link>
    <joint name="a_bot_ee_gripper" type="fixed">
        <axis xyz="1 0 0" />
        <origin rpy="0 0 0" xyz="0.0385 0 0" />
        <parent link="a_bot_fingers_link" />
        <child link="a_bot_ee_gripper_link" />
    </joint>
    <!-- no visual -->
    <link name="a_bot_ee_gripper_link">
        <inertial>
            <mass value="0.001" />
            <inertia ixx="0.0001" ixy="0" ixz="0" iyy="0.0001" iyz="0" izz="0.0001" />
        </inertial>
    </link>
    <transmission name="b_bot_waist_trans">
        <type>transmission_interface/SimpleTransmission</type>
        <joint name="b_bot_waist">
            <hardwareInterface>hardware_interface/EffortJointInterface</hardwareInterface>
        </joint>
        <actuator name="b_bot_waist_motor">
            <mechanicalReduction>1</mechanicalReduction>
            <hardwareInterface>hardware_interface/EffortJointInterface</hardwareInterface>
        </actuator>
    </transmission>
    <transmission name="b_bot_shoulder_trans">
        <type>transmission_interface/SimpleTransmission</type>
        <joint name="b_bot_shoulder">
            <hardwareInterface>hardware_interface/EffortJointInterface</hardwareInterface>
        </joint>
        <actuator name="b_bot_shoulder_motor">
            <mechanicalReduction>1</mechanicalReduction>
            <hardwareInterface>hardware_interface/EffortJointInterface</hardwareInterface>
        </actuator>
    </transmission>
    <transmission name="b_bot_elbow_trans">
        <type>transmission_interface/SimpleTransmission</type>
        <joint name="b_bot_elbow">
            <hardwareInterface>hardware_interface/EffortJointInterface</hardwareInterface>
        </joint>
        <actuator name="b_bot_elbow_motor">
            <mechanicalReduction>1</mechanicalReduction>
            <hardwareInterface>hardware_interface/EffortJointInterface</hardwareInterface>
        </actuator>
    </transmission>
    <transmission name="b_bot_forearm_roll_trans">
        <type>transmission_interface/SimpleTransmission</type>
        <joint name="b_bot_forearm_roll">
            <hardwareInterface>hardware_interface/EffortJointInterface</hardwareInterface>
        </joint>
        <actuator name="b_bot_forearm_roll_motor">
            <mechanicalReduction>1</mechanicalReduction>
            <hardwareInterface>hardware_interface/EffortJointInterface</hardwareInterface>
        </actuator>
    </transmission>
    <transmission name="b_bot_wrist_angle_trans">
        <type>transmission_interface/SimpleTransmission</type>
        <joint name="b_bot_wrist_angle">
            <hardwareInterface>hardware_interface/EffortJointInterface</hardwareInterface>
        </joint>
        <actuator name="b_bot_wrist_angle_motor">
            <mechanicalReduction>1</mechanicalReduction>
            <hardwareInterface>hardware_interface/EffortJointInterface</hardwareInterface>
        </actuator>
    </transmission>
    <transmission name="b_bot_wrist_rotate_trans">
        <type>transmission_interface/SimpleTransmission</type>
        <joint name="b_bot_wrist_rotate">
            <hardwareInterface>hardware_interface/EffortJointInterface</hardwareInterface>
        </joint>
        <actuator name="b_bot_wrist_rotate_motor">
            <mechanicalReduction>1</mechanicalReduction>
            <hardwareInterface>hardware_interface/EffortJointInterface</hardwareInterface>
        </actuator>
    </transmission>
    <transmission name="b_bot_left_finger_trans">
        <type>transmission_interface/SimpleTransmission</type>
        <joint name="b_bot_left_finger">
            <hardwareInterface>hardware_interface/EffortJointInterface</hardwareInterface>
        </joint>
        <actuator name="b_bot_left_finger_motor">
            <mechanicalReduction>1</mechanicalReduction>
            <hardwareInterface>hardware_interface/EffortJointInterface</hardwareInterface>
        </actuator>
    </transmission>
    <transmission name="b_bot_right_finger_trans">
        <type>transmission_interface/SimpleTransmission</type>
        <joint name="b_bot_right_finger">
            <hardwareInterface>hardware_interface/EffortJointInterface</hardwareInterface>
        </joint>
        <actuator name="b_bot_right_finger_motor">
            <mechanicalReduction>1</mechanicalReduction>
            <hardwareInterface>hardware_interface/EffortJointInterface</hardwareInterface>
        </actuator>
    </transmission>
    <gazebo reference="b_bot_base_link">
        <kp>1000000.0</kp>
        <kd>1.0</kd>
        <mu1>0.8</mu1>
        <mu2>0.8</mu2>
        <maxVel>0.0</maxVel>
        <minDepth>0.001</minDepth>
        <selfCollide>true</selfCollide>
    </gazebo>
    <gazebo reference="b_bot_shoulder_link">
        <kp>1000000.0</kp>
        <kd>1.0</kd>
        <mu1>0.8</mu1>
        <mu2>0.8</mu2>
        <maxVel>0.0</maxVel>
        <minDepth>0.001</minDepth>
        <selfCollide>true</selfCollide>
    </gazebo>
    <gazebo reference="b_bot_upper_arm_link">
        <kp>1000000.0</kp>
        <kd>1.0</kd>
        <mu1>0.8</mu1>
        <mu2>0.8</mu2>
        <maxVel>0.0</maxVel>
        <minDepth>0.001</minDepth>
        <selfCollide>true</selfCollide>
    </gazebo>
    <gazebo reference="b_bot_upper_forearm_link">
        <kp>1000000.0</kp>
        <kd>1.0</kd>
        <mu1>0.8</mu1>
        <mu2>0.8</mu2>
        <maxVel>0.0</maxVel>
        <minDepth>0.001</minDepth>
        <selfCollide>true</selfCollide>
    </gazebo>
    <gazebo reference="b_bot_lower_forearm_link">
        <kp>1000000.0</kp>
        <kd>1.0</kd>
        <mu1>0.8</mu1>
        <mu2>0.8</mu2>
        <maxVel>0.0</maxVel>
        <minDepth>0.001</minDepth>
        <selfCollide>true</selfCollide>
    </gazebo>
    <gazebo reference="b_bot_wrist_link">
        <kp>1000000.0</kp>
        <kd>1.0</kd>
        <mu1>0.8</mu1>
        <mu2>0.8</mu2>
        <maxVel>0.0</maxVel>
        <minDepth>0.001</minDepth>
        <selfCollide>true</selfCollide>
    </gazebo>
    <gazebo reference="b_bot_gripper_link">
        <kp>1000000.0</kp>
        <kd>1.0</kd>
        <mu1>0.8</mu1>
        <mu2>0.8</mu2>
        <maxVel>0.0</maxVel>
        <minDepth>0.001</minDepth>
        <selfCollide>true</selfCollide>
    </gazebo>
    <gazebo reference="b_bot_gripper_prop_link">
        <kp>1000000.0</kp>
        <kd>1.0</kd>
        <mu1>0.8</mu1>
        <mu2>0.8</mu2>
        <maxVel>0.0</maxVel>
        <minDepth>0.001</minDepth>
        <selfCollide>true</selfCollide>
    </gazebo>
    <gazebo reference="b_bot_gripper_bar_link">
        <kp>1000000.0</kp>
        <kd>1.0</kd>
        <mu1>0.8</mu1>
        <mu2>0.8</mu2>
        <maxVel>0.0</maxVel>
        <minDepth>0.001</minDepth>
        <selfCollide>true</selfCollide>
    </gazebo>
    <gazebo reference="b_bot_left_finger_link">
        <kp>1000000.0</kp>
        <kd>1.0</kd>
        <mu1>0.8</mu1>
        <mu2>0.8</mu2>
        <maxVel>0.0</maxVel>
        <minDepth>0.001</minDepth>
        <selfCollide>true</selfCollide>
    </gazebo>
    <gazebo reference="b_bot_right_finger_link">
        <kp>1000000.0</kp>
        <kd>1.0</kd>
        <mu1>0.8</mu1>
        <mu2>0.8</mu2>
        <maxVel>0.0</maxVel>
        <minDepth>0.001</minDepth>
        <selfCollide>true</selfCollide>
    </gazebo>
    <gazebo reference="b_bot_waist">
        <implicitSpringDamper>true</implicitSpringDamper>
        <disableFixedJointLumping>true</disableFixedJointLumping>
    </gazebo>
    <gazebo reference="b_bot_shoulder">
        <implicitSpringDamper>true</implicitSpringDamper>
        <disableFixedJointLumping>true</disableFixedJointLumping>
    </gazebo>
    <gazebo reference="b_bot_elbow">
        <implicitSpringDamper>true</implicitSpringDamper>
        <disableFixedJointLumping>true</disableFixedJointLumping>
    </gazebo>
    <gazebo reference="b_bot_forearm_roll">
        <implicitSpringDamper>true</implicitSpringDamper>
        <disableFixedJointLumping>true</disableFixedJointLumping>
    </gazebo>
    <gazebo reference="b_bot_wrist_angle">
        <implicitSpringDamper>true</implicitSpringDamper>
        <disableFixedJointLumping>true</disableFixedJointLumping>
    </gazebo>
    <gazebo reference="b_bot_wrist_rotate">
        <implicitSpringDamper>true</implicitSpringDamper>
        <disableFixedJointLumping>true</disableFixedJointLumping>
    </gazebo>
    <gazebo reference="b_bot_ee_arm">
        <implicitSpringDamper>true</implicitSpringDamper>
        <disableFixedJointLumping>true</disableFixedJointLumping>
    </gazebo>
    <gazebo reference="b_bot_gripper">
        <implicitSpringDamper>true</implicitSpringDamper>
        <disableFixedJointLumping>true</disableFixedJointLumping>
    </gazebo>
    <gazebo reference="b_bot_gripper_bar">
        <implicitSpringDamper>true</implicitSpringDamper>
        <disableFixedJointLumping>true</disableFixedJointLumping>
    </gazebo>
    <gazebo reference="b_bot_ee_bar">
        <implicitSpringDamper>true</implicitSpringDamper>
        <disableFixedJointLumping>true</disableFixedJointLumping>
    </gazebo>
    <gazebo reference="b_bot_left_finger">
        <implicitSpringDamper>true</implicitSpringDamper>
        <disableFixedJointLumping>true</disableFixedJointLumping>
    </gazebo>
    <gazebo reference="b_bot_right_finger">
        <implicitSpringDamper>true</implicitSpringDamper>
        <disableFixedJointLumping>true</disableFixedJointLumping>
    </gazebo>
    <gazebo reference="b_bot_ee_gripper">
        <implicitSpringDamper>true</implicitSpringDamper>
        <disableFixedJointLumping>true</disableFixedJointLumping>
    </gazebo>
    <link name="b_bot_base_link">
        <visual>
            <origin rpy="0 0 1.5707963267948966" xyz="0 0 0" />
            <geometry>
                <mesh filename="package://interbotix_xsarm_descriptions/meshes/vx300s_meshes/vx300s_1_base.stl" scale="0.001 0.001 0.001" />
            </geometry>
            <material name="interbotix_black" />
        </visual>
        <collision>
            <origin rpy="0 0 1.5707963267948966" xyz="0 0 0" />
            <geometry>
                <mesh filename="package://interbotix_xsarm_descriptions/meshes/vx300s_meshes/vx300s_1_base.stl" scale="0.001 0.001 0.001" />
            </geometry>
        </collision>
        <inertial>
            <origin rpy="0 0 1.5707963267948966" xyz="-0.0534774000 -0.0005625750 0.0205961000" />
            <mass value="0.969034" />
            <inertia ixx="0.0060240000" ixy="0.0000471300" ixz="0.0000038510" iyy="0.0017000000" iyz="-0.0000841500" izz="0.0071620000" />
        </inertial>
    </link>
    <joint name="b_bot_waist" type="revolute">
        <axis xyz="0 0 1" />
        <limit effort="10" lower="-3.141582653589793" upper="3.141582653589793" velocity="3.141592653589793" />
        <origin rpy="0 0 0" xyz="0 0 0.079" />
        <parent link="b_bot_base_link" />
        <child link="b_bot_shoulder_link" />
        <dynamics friction="0.1" />
    </joint>
    <link name="b_bot_shoulder_link">
        <visual>
            <origin rpy="0 0 1.5707963267948966" xyz="0 0 -0.003" />
            <geometry>
                <mesh filename="package://interbotix_xsarm_descriptions/meshes/vx300s_meshes/vx300s_2_shoulder.stl" scale="0.001 0.001 0.001" />
            </geometry>
            <material name="interbotix_black" />
        </visual>
        <collision>
            <origin rpy="0 0 1.5707963267948966" xyz="0 0 -0.003" />
            <geometry>
                <mesh filename="package://interbotix_xsarm_descriptions/meshes/vx300s_meshes/vx300s_2_shoulder.stl" scale="0.001 0.001 0.001" />
            </geometry>
        </collision>
        <inertial>
            <origin rpy="0 0 1.5707963267948966" xyz="0.0002592330 -0.0000033552 0.0116129000" />
            <mass value="0.798614" />
            <inertia ixx="0.0009388000" ixy="-0.0000000010" ixz="-0.0000000191" iyy="0.0011380000" iyz="0.0000059568" izz="0.0012010000" />
        </inertial>
    </link>
    <joint name="b_bot_shoulder" type="revolute">
        <axis xyz="0 1 0" />
        <limit effort="20" lower="-1.8500490071139892" upper="1.2566370614359172" velocity="3.141592653589793" />
        <origin rpy="0 0 0" xyz="0 0 0.04805" />
        <parent link="b_bot_shoulder_link" />
        <child link="b_bot_upper_arm_link" />
        <dynamics friction="0.1" />
    </joint>
    <link name="b_bot_upper_arm_link">
        <visual>
            <origin rpy="0 0 1.5707963267948966" xyz="0 0 0" />
            <geometry>
                <mesh filename="package://interbotix_xsarm_descriptions/meshes/vx300s_meshes/vx300s_3_upper_arm.stl" scale="0.001 0.001 0.001" />
            </geometry>
            <material name="interbotix_black" />
        </visual>
        <collision>
            <origin rpy="0 0 1.5707963267948966" xyz="0 0 0" />
            <geometry>
                <mesh filename="package://interbotix_xsarm_descriptions/meshes/vx300s_meshes/vx300s_3_upper_arm.stl" scale="0.001 0.001 0.001" />
            </geometry>
        </collision>
        <inertial>
            <origin rpy="0 0 1.5707963267948966" xyz="0.0206949000 0.0000000004 0.2264590000" />
            <mass value="0.792592" />
            <inertia ixx="0.0089250000" ixy="0.0000000000" ixz="0.0000000000" iyy="0.0089370000" iyz="0.0012010000" izz="0.0009357000" />
        </inertial>
    </link>
    <joint name="b_bot_elbow" type="revolute">
        <axis xyz="0 1 0" />
        <limit effort="15" lower="-1.7627825445142729" upper="1.6057029118347832" velocity="3.141592653589793" />
        <origin rpy="0 0 0" xyz="0.05955 0 0.3" />
        <parent link="b_bot_upper_arm_link" />
        <child link="b_bot_upper_forearm_link" />
        <dynamics friction="0.1" />
    </joint>
    <link name="b_bot_upper_forearm_link">
        <visual>
            <origin rpy="0 0 0" xyz="0 0 0" />
            <geometry>
                <mesh filename="package://interbotix_xsarm_descriptions/meshes/vx300s_meshes/vx300s_4_upper_forearm.stl" scale="0.001 0.001 0.001" />
            </geometry>
            <material name="interbotix_black" />
        </visual>
        <collision>
            <origin rpy="0 0 0" xyz="0 0 0" />
            <geometry>
                <mesh filename="package://interbotix_xsarm_descriptions/meshes/vx300s_meshes/vx300s_4_upper_forearm.stl" scale="0.001 0.001 0.001" />
            </geometry>
        </collision>
        <inertial>
            <origin rpy="0 0 0" xyz="0.105723 0 0" />
            <mass value="0.322228" />
            <inertia ixx="0.0001524000" ixy="-0.0000188300" ixz="-0.0000084064" iyy="0.0013420000" iyz="0.0000012564" izz="0.0014410000" />
        </inertial>
    </link>
    <joint name="b_bot_forearm_roll" type="revolute">
        <axis xyz="1 0 0" />
        <limit effort="2" lower="-3.141582653589793" upper="3.141582653589793" velocity="3.141592653589793" />
        <origin rpy="0 0 0" xyz="0.2 0 0" />
        <parent link="b_bot_upper_forearm_link" />
        <child link="b_bot_lower_forearm_link" />
        <dynamics friction="0.1" />
    </joint>
    <link name="b_bot_lower_forearm_link">
        <visual>
            <origin rpy="3.141592653589793 0 0" xyz="0 0 0" />
            <geometry>
                <mesh filename="package://interbotix_xsarm_descriptions/meshes/vx300s_meshes/vx300s_5_lower_forearm.stl" scale="0.001 0.001 0.001" />
            </geometry>
            <material name="interbotix_black" />
        </visual>
        <collision>
            <origin rpy="3.141592653589793 0 0" xyz="0 0 0" />
            <geometry>
                <mesh filename="package://interbotix_xsarm_descriptions/meshes/vx300s_meshes/vx300s_5_lower_forearm.stl" scale="0.001 0.001 0.001" />
            </geometry>
        </collision>
        <inertial>
            <origin rpy="3.141592653589793 0 0" xyz="0.0513477000 0.0068046200 0" />
            <mass value="0.414823" />
            <inertia ixx="0.0001753000" ixy="-0.0000852800" ixz="0" iyy="0.0005269000" iyz="0" izz="0.0005911000" />
        </inertial>
    </link>
    <joint name="b_bot_wrist_angle" type="revolute">
        <axis xyz="0 1 0" />
        <limit effort="5" lower="-1.8675022996339325" upper="2.234021442552742" velocity="3.141592653589793" />
        <origin rpy="0 0 0" xyz="0.1 0 0" />
        <parent link="b_bot_lower_forearm_link" />
        <child link="b_bot_wrist_link" />
        <dynamics friction="0.1" />
    </joint>
    <link name="b_bot_wrist_link">
        <visual>
            <origin rpy="0 0 1.5707963267948966" xyz="0 0 0" />
            <geometry>
                <mesh filename="package://interbotix_xsarm_descriptions/meshes/vx300s_meshes/vx300s_6_wrist.stl" scale="0.001 0.001 0.001" />
            </geometry>
            <material name="interbotix_black" />
        </visual>
        <collision>
            <origin rpy="0 0 1.5707963267948966" xyz="0 0 0" />
            <geometry>
                <mesh filename="package://interbotix_xsarm_descriptions/meshes/vx300s_meshes/vx300s_6_wrist.stl" scale="0.001 0.001 0.001" />
            </geometry>
        </collision>
        <inertial>
            <origin rpy="0 0 1.5707963267948966" xyz="0.0467430000 -0.0000076652 0.0105650000" />
            <mass value="0.115395" />
            <inertia ixx="0.0000463100" ixy="0.0000000195" ixz="0.0000000023" iyy="0.0000451400" iyz="0.0000042002" izz="0.0000527000" />
        </inertial>
    </link>
    <joint name="b_bot_wrist_rotate" type="revolute">
        <axis xyz="1 0 0" />
        <limit effort="1" lower="-3.141582653589793" upper="3.141582653589793" velocity="3.141592653589793" />
        <origin rpy="0 0 0" xyz="0.069744 0 0" />
        <parent link="b_bot_wrist_link" />
        <child link="b_bot_gripper_link" />
        <dynamics friction="0.1" />
    </joint>
    <link name="b_bot_gripper_link">
        <visual>
            <origin rpy="0 0 1.5707963267948966" xyz="-0.02 0 0" />
            <geometry>
                <mesh filename="package://interbotix_xsarm_descriptions/meshes/vx300s_meshes/vx300s_7_gripper.stl" scale="0.001 0.001 0.001" />
            </geometry>
            <material name="interbotix_black" />
        </visual>
        <collision>
            <origin rpy="0 0 1.5707963267948966" xyz="-0.02 0 0" />
            <geometry>
                <mesh filename="package://interbotix_xsarm_descriptions/meshes/vx300s_meshes/vx300s_7_gripper.stl" scale="0.001 0.001 0.001" />
            </geometry>
        </collision>
        <inertial>
            <origin rpy="0 0 1.5707963267948966" xyz="0.0230010000 0.0000000000 0.0115230000" />
            <mass value="0.097666" />
            <inertia ixx="0.0000326800" ixy="0.0000000000" ixz="0.0000000000" iyy="0.0000243600" iyz="0.0000002785" izz="0.0000211900" />
        </inertial>
    </link>
    <joint name="b_bot_ee_arm" type="fixed">
        <axis xyz="1 0 0" />
        <origin rpy="0 0 0" xyz="0.042825 0 0" />
        <parent link="b_bot_gripper_link" />
        <child link="b_bot_ee_arm_link" />
    </joint>
    <!-- no visual -->
    <link name="b_bot_ee_arm_link">
        <inertial>
            <mass value="0.001" />
            <inertia ixx="0.0001" ixy="0" ixz="0" iyy="0.0001" iyz="0" izz="0.0001" />
        </inertial>
    </link>
    <joint name="b_bot_gripper_bar" type="fixed">
        <axis xyz="1 0 0" />
        <origin rpy="0 0 0" xyz="0 0 0" />
        <parent link="b_bot_ee_arm_link" />
        <child link="b_bot_gripper_bar_link" />
    </joint>
    <link name="b_bot_gripper_bar_link">
        <visual>
            <origin rpy="0 0 1.5707963267948966" xyz="-0.063 0 0" />
            <geometry>
                <mesh filename="package://interbotix_xsarm_descriptions/meshes/vx300s_meshes/vx300s_9_gripper_bar.stl" scale="0.001 0.001 0.001" />
            </geometry>
            <material name="interbotix_black" />
        </visual>
        <collision>
            <origin rpy="0 0 1.5707963267948966" xyz="-0.063 0 0" />
            <geometry>
                <mesh filename="package://interbotix_xsarm_descriptions/meshes/vx300s_meshes/vx300s_9_gripper_bar.stl" scale="0.001 0.001 0.001" />
            </geometry>
        </collision>
        <inertial>
            <origin rpy="0 0 1.5707963267948966" xyz="0.0067940000 -0.0000004272 -0.0007760000" />
            <mass value="0.150986" />
            <inertia ixx="0.0000789500" ixy="-0.0000000012" ixz="0.0000001341" iyy="0.0003283000" iyz="0.0000017465" izz="0.0003095000" />
        </inertial>
    </link>
    <joint name="b_bot_ee_bar" type="fixed">
        <axis xyz="1 0 0" />
        <origin rpy="0 0 0" xyz="0.025875 0 0" />
        <parent link="b_bot_gripper_bar_link" />
        <child link="b_bot_fingers_link" />
    </joint>
    <!-- no visual -->
    <link name="b_bot_fingers_link">
        <inertial>
            <mass value="0.001" />
            <inertia ixx="0.0001" ixy="0" ixz="0" iyy="0.0001" iyz="0" izz="0.0001" />
        </inertial>
    </link>
    <joint name="b_bot_left_finger" type="prismatic">
        <axis xyz="0 1 0" />
        <limit effort="5" lower="0.021" upper="0.057" velocity="1" />
        <origin rpy="0 0 0" xyz="0 0 0" />
        <parent link="b_bot_fingers_link" />
        <child link="b_bot_left_finger_link" />
        <dynamics friction="0.1" />
    </joint>
    <link name="b_bot_left_finger_link">
        <visual>
            <origin rpy="1.5707963267948966 -3.141592653589793 1.5707963267948966" xyz="-0.0404 -0.0575 0" />
            <geometry>
                <mesh filename="package://interbotix_xsarm_descriptions/meshes/vx300s_meshes/vx300s_10_gripper_finger.stl" scale="0.001 0.001 0.001" />
            </geometry>
            <material name="interbotix_black" />
        </visual>
        <collision>
            <origin rpy="1.5707963267948966 -3.141592653589793 1.5707963267948966" xyz="-0.0404 -0.0575 0" />
            <geometry>
                <mesh filename="package://interbotix_xsarm_descriptions/meshes/vx300s_meshes/vx300s_10_gripper_finger.stl" scale="0.001 0.001 0.001" />
            </geometry>
        </collision>
        <inertial>
            <origin rpy="3.141592653589793 3.141592653589793 1.5707963267948966" xyz="0.0173440000 -0.0060692000 0.0000000000" />
            <mass value="0.034796" />
            <inertia ixx="0.0000243300" ixy="-0.0000024004" ixz="0.0000000000" iyy="0.0000125500" iyz="0.0000000000" izz="0.0000141700" />
        </inertial>
    </link>
    <joint name="b_bot_right_finger" type="prismatic">
        <axis xyz="0 1 0" />
        <limit effort="5" lower="-0.057" upper="-0.021" velocity="1" />
        <origin rpy="0 0 0" xyz="0 0 0" />
        <parent link="b_bot_fingers_link" />
        <child link="b_bot_right_finger_link" />
        <dynamics friction="0.1" />
        <mimic joint="b_bot_left_finger" multiplier="-1" offset="0" />
    </joint>
    <link name="b_bot_right_finger_link">
        <visual>
            <origin rpy="-1.5707963267948966 3.141592653589793 -1.5707963267948966" xyz="-0.0404 0.0575 0 " />
            <geometry>
                <mesh filename="package://interbotix_xsarm_descriptions/meshes/vx300s_meshes/vx300s_10_gripper_finger.stl" scale="0.001 0.001 0.001" />
            </geometry>
            <material name="interbotix_black" />
        </visual>
        <collision>
            <origin rpy="-1.5707963267948966 3.141592653589793 -1.5707963267948966" xyz="-0.0404 0.0575 0 " />
            <geometry>
                <mesh filename="package://interbotix_xsarm_descriptions/meshes/vx300s_meshes/vx300s_10_gripper_finger.stl" scale="0.001 0.001 0.001" />
            </geometry>
        </collision>
        <inertial>
            <origin rpy="0 3.141592653589793 1.5707963267948966" xyz="0.0173440000 0.0060692000  0.0000000000" />
            <mass value="0.034796" />
            <inertia ixx="0.0000243300" ixy="0.0000024001" ixz="0.0000000000" iyy="0.0000125500" iyz="0.0000000000" izz="0.0000141700" />
        </inertial>
    </link>
    <joint name="b_bot_ee_gripper" type="fixed">
        <axis xyz="1 0 0" />
        <origin rpy="0 0 0" xyz="0.0385 0 0" />
        <parent link="b_bot_fingers_link" />
        <child link="b_bot_ee_gripper_link" />
    </joint>
    <!-- no visual -->
    <link name="b_bot_ee_gripper_link">
        <inertial>
            <mass value="0.001" />
            <inertia ixx="0.0001" ixy="0" ixz="0" iyy="0.0001" iyz="0" izz="0.0001" />
        </inertial>
    </link>
    <joint name="a_bot_to_world" type="fixed">
        <parent link="world" />
        <child link="a_bot_base_link" />
        <origin xyz="0 -0.1778 0" />
    </joint>
    <joint name="b_bot_to_world" type="fixed">
        <parent link="world" />
        <child link="b_bot_base_link" />
        <origin xyz="0 0.1778 0" />
    </joint>
    <!-- gazebo ros control plugin -->
    <gazebo>
        <plugin filename="libgazebo_ros_control.so" name="gazebo_ros_control">
            <robotSimType>gazebo_ros_control/DefaultRobotHWSim</robotSimType>
            <legacyModeNS>true</legacyModeNS>
        </plugin>
    </gazebo>
</robot>

